import React from 'react';
import { render, screen } from '../utils/test-utils';
import { ErrorBoundary } from '../../components/error/ErrorBoundary';

// Component that throws an error
const ThrowError: React.FC<{ shouldThrow?: boolean }> = ({ shouldThrow = true }) => {
  if (shouldThrow) {
    throw new Error('Test error');
  }
  return <div>No error</div>;
};

describe('ErrorBoundary', () => {
  beforeEach(() => {
    // Suppress console.error for these tests
    vi.spyOn(console, 'error').mockImplementation(() => {});
  });

  afterEach(() => {
    vi.restoreAllMocks();
  });

  it('renders children when there is no error', () => {
    render(
      <ErrorBoundary>
        <ThrowError shouldThrow={false} />
      </ErrorBoundary>
    );

    expect(screen.getByText('No error')).toBeInTheDocument();
  });

  it('renders error UI when there is an error', () => {
    render(
      <ErrorBoundary>
        <ThrowError />
      </ErrorBoundary>
    );

    expect(screen.getByText('Something went wrong')).toBeInTheDocument();
    expect(screen.getByText(/We're sorry, but something unexpected happened/)).toBeInTheDocument();
    expect(screen.getByRole('button', { name: /try again/i })).toBeInTheDocument();
  });

  it('renders custom fallback when provided', () => {
    const customFallback = <div>Custom error message</div>;

    render(
      <ErrorBoundary fallback={customFallback}>
        <ThrowError />
      </ErrorBoundary>
    );

    expect(screen.getByText('Custom error message')).toBeInTheDocument();
  });

  it('calls onError callback when error occurs', () => {
    const onError = vi.fn();

    render(
      <ErrorBoundary onError={onError}>
        <ThrowError />
      </ErrorBoundary>
    );

    expect(onError).toHaveBeenCalledWith(
      expect.any(Error),
      expect.objectContaining({
        componentStack: expect.any(String),
      })
    );
  });

  it('resets error state when retry button is clicked', async () => {
    const { rerender } = render(
      <ErrorBoundary>
        <ThrowError />
      </ErrorBoundary>
    );

    expect(screen.getByText('Something went wrong')).toBeInTheDocument();

    const retryButton = screen.getByRole('button', { name: /try again/i });
    await userEvent.click(retryButton);

    // Re-render with non-throwing component
    rerender(
      <ErrorBoundary>
        <ThrowError shouldThrow={false} />
      </ErrorBoundary>
    );

    expect(screen.getByText('No error')).toBeInTheDocument();
  });
});